02/11/2015 00:34:25 WARNING nemoa.log -> could not get configuration: dataset with name 'linear' is not found in common workspace 'benchmark'.
02/11/2015 00:34:25 ERROR nemoa.log -> could not import dataset: workspace 'None' does not contain a dataset with name 'linear'.
02/11/2015 00:34:25 ERROR File "testnemoa.py", line 66, in <module>->   unittest.main()
02/11/2015 00:34:25 ERROR File "C:\Python27\lib\unittest\main.py", line 95, in __init__->   self.runTests()
02/11/2015 00:34:25 ERROR File "C:\Python27\lib\unittest\main.py", line 232, in runTests->   self.result = testRunner.run(self.test)
02/11/2015 00:34:25 ERROR File "C:\Python27\lib\unittest\runner.py", line 151, in run->   test(result)
02/11/2015 00:34:25 ERROR File "C:\Python27\lib\unittest\suite.py", line 70, in __call__->   return self.run(*args, **kwds)
02/11/2015 00:34:25 ERROR File "C:\Python27\lib\unittest\suite.py", line 108, in run->   test(result)
02/11/2015 00:34:25 ERROR File "C:\Python27\lib\unittest\suite.py", line 70, in __call__->   return self.run(*args, **kwds)
02/11/2015 00:34:25 ERROR File "C:\Python27\lib\unittest\suite.py", line 108, in run->   test(result)
02/11/2015 00:34:25 ERROR File "C:\Python27\lib\unittest\case.py", line 393, in __call__->   return self.run(*args, **kwds)
02/11/2015 00:34:25 ERROR File "C:\Python27\lib\unittest\case.py", line 329, in run->   testMethod()
02/11/2015 00:34:25 ERROR File "testnemoa.py", line 24, in test_dataset_import_tab->   test = nemoa.common.type.isdataset(nemoa.dataset.open('linear'))
02/11/2015 00:34:25 ERROR File "./package\nemoa\dataset\__init__.py", line 35, in open->   return new(**load(*args, **kwargs))
02/11/2015 00:34:25 ERROR File "./package\nemoa\dataset\__init__.py", line 27, in load->   return nemoa.dataset.imports.load(*args, **kwargs)
02/11/2015 00:34:25 ERROR File "./package\nemoa\dataset\imports\__init__.py", line 44, in load->   '%s'.""" % (workspace, path))
02/11/2015 00:34:25 ERROR File "./package\nemoa\__init__.py", line 32, in log->   return nemoa.common.log.log(*args, **kwargs)
02/11/2015 00:34:25 ERROR File "./package\nemoa\common\log.py", line 174, in log->   for line in traceback.format_stack():
02/11/2015 00:34:25 WARNING nemoa.log -> could not open workspace 'unittest': folder could not be found in './user/'.
02/11/2015 00:34:25 WARNING nemoa.log -> could not open workspace 'unittest': folder could not be found in './user/'.
02/11/2015 00:34:25 WARNING nemoa.log -> could not get configuration: dataset with name 'linear' is not found in common workspace 'benchmark'.
02/11/2015 00:34:25 ERROR nemoa.log -> could not import dataset: workspace 'None' does not contain a dataset with name 'linear'.
02/11/2015 00:34:25 ERROR File "testnemoa.py", line 66, in <module>->   unittest.main()
02/11/2015 00:34:25 ERROR File "C:\Python27\lib\unittest\main.py", line 95, in __init__->   self.runTests()
02/11/2015 00:34:25 ERROR File "C:\Python27\lib\unittest\main.py", line 232, in runTests->   self.result = testRunner.run(self.test)
02/11/2015 00:34:25 ERROR File "C:\Python27\lib\unittest\runner.py", line 151, in run->   test(result)
02/11/2015 00:34:25 ERROR File "C:\Python27\lib\unittest\suite.py", line 70, in __call__->   return self.run(*args, **kwds)
02/11/2015 00:34:25 ERROR File "C:\Python27\lib\unittest\suite.py", line 108, in run->   test(result)
02/11/2015 00:34:25 ERROR File "C:\Python27\lib\unittest\suite.py", line 70, in __call__->   return self.run(*args, **kwds)
02/11/2015 00:34:25 ERROR File "C:\Python27\lib\unittest\suite.py", line 108, in run->   test(result)
02/11/2015 00:34:25 ERROR File "C:\Python27\lib\unittest\case.py", line 393, in __call__->   return self.run(*args, **kwds)
02/11/2015 00:34:25 ERROR File "C:\Python27\lib\unittest\case.py", line 329, in run->   testMethod()
02/11/2015 00:34:25 ERROR File "testnemoa.py", line 60, in test_model_algorithm_deep_dbn->   dataset = 'linear', network = 'deep', system = 'dbn')
02/11/2015 00:34:25 ERROR File "./package\nemoa\model\__init__.py", line 22, in create->   return new(**build(*args, **kwargs))
02/11/2015 00:34:25 ERROR File "./package\nemoa\model\__init__.py", line 14, in build->   return nemoa.model.builder.build(*args, **kwargs)
02/11/2015 00:34:25 ERROR File "./package\nemoa\model\builder\__init__.py", line 38, in build->   model = nemoa.model.builder.base.build(type, *args, **kwargs)
02/11/2015 00:34:25 ERROR File "./package\nemoa\model\builder\base.py", line 20, in build->   if type == 'model': return Model(**kwargs).build()
02/11/2015 00:34:25 ERROR File "./package\nemoa\model\builder\base.py", line 77, in build->   = nemoa.dataset.load(self.settings['dataset'])
02/11/2015 00:34:25 ERROR File "./package\nemoa\dataset\__init__.py", line 27, in load->   return nemoa.dataset.imports.load(*args, **kwargs)
02/11/2015 00:34:25 ERROR File "./package\nemoa\dataset\imports\__init__.py", line 44, in load->   '%s'.""" % (workspace, path))
02/11/2015 00:34:25 ERROR File "./package\nemoa\__init__.py", line 32, in log->   return nemoa.common.log.log(*args, **kwargs)
02/11/2015 00:34:25 ERROR File "./package\nemoa\common\log.py", line 174, in log->   for line in traceback.format_stack():
02/11/2015 00:34:25 ERROR nemoa.log -> could not optimize model: dataset is not valid.
02/11/2015 00:34:25 ERROR File "testnemoa.py", line 66, in <module>->   unittest.main()
02/11/2015 00:34:25 ERROR File "C:\Python27\lib\unittest\main.py", line 95, in __init__->   self.runTests()
02/11/2015 00:34:25 ERROR File "C:\Python27\lib\unittest\main.py", line 232, in runTests->   self.result = testRunner.run(self.test)
02/11/2015 00:34:25 ERROR File "C:\Python27\lib\unittest\runner.py", line 151, in run->   test(result)
02/11/2015 00:34:25 ERROR File "C:\Python27\lib\unittest\suite.py", line 70, in __call__->   return self.run(*args, **kwds)
02/11/2015 00:34:25 ERROR File "C:\Python27\lib\unittest\suite.py", line 108, in run->   test(result)
02/11/2015 00:34:25 ERROR File "C:\Python27\lib\unittest\suite.py", line 70, in __call__->   return self.run(*args, **kwds)
02/11/2015 00:34:25 ERROR File "C:\Python27\lib\unittest\suite.py", line 108, in run->   test(result)
02/11/2015 00:34:25 ERROR File "C:\Python27\lib\unittest\case.py", line 393, in __call__->   return self.run(*args, **kwds)
02/11/2015 00:34:25 ERROR File "C:\Python27\lib\unittest\case.py", line 329, in run->   testMethod()
02/11/2015 00:34:25 ERROR File "testnemoa.py", line 61, in test_model_algorithm_deep_dbn->   model.optimize()
02/11/2015 00:34:25 ERROR File "./package\nemoa\model\classes\base.py", line 127, in optimize->   dataset is not valid.""")
02/11/2015 00:34:25 ERROR File "./package\nemoa\__init__.py", line 32, in log->   return nemoa.common.log.log(*args, **kwargs)
02/11/2015 00:34:25 ERROR File "./package\nemoa\common\log.py", line 174, in log->   for line in traceback.format_stack():
02/11/2015 00:34:25 WARNING nemoa.log -> could not open workspace 'unittest': folder could not be found in './user/'.
02/11/2015 00:34:25 WARNING nemoa.log -> could not get configuration: dataset with name 'linear' is not found in common workspace 'benchmark'.
02/11/2015 00:34:25 ERROR nemoa.log -> could not import dataset: workspace 'None' does not contain a dataset with name 'linear'.
02/11/2015 00:34:25 ERROR File "testnemoa.py", line 66, in <module>->   unittest.main()
02/11/2015 00:34:25 ERROR File "C:\Python27\lib\unittest\main.py", line 95, in __init__->   self.runTests()
02/11/2015 00:34:25 ERROR File "C:\Python27\lib\unittest\main.py", line 232, in runTests->   self.result = testRunner.run(self.test)
02/11/2015 00:34:25 ERROR File "C:\Python27\lib\unittest\runner.py", line 151, in run->   test(result)
02/11/2015 00:34:25 ERROR File "C:\Python27\lib\unittest\suite.py", line 70, in __call__->   return self.run(*args, **kwds)
02/11/2015 00:34:25 ERROR File "C:\Python27\lib\unittest\suite.py", line 108, in run->   test(result)
02/11/2015 00:34:25 ERROR File "C:\Python27\lib\unittest\suite.py", line 70, in __call__->   return self.run(*args, **kwds)
02/11/2015 00:34:25 ERROR File "C:\Python27\lib\unittest\suite.py", line 108, in run->   test(result)
02/11/2015 00:34:25 ERROR File "C:\Python27\lib\unittest\case.py", line 393, in __call__->   return self.run(*args, **kwds)
02/11/2015 00:34:25 ERROR File "C:\Python27\lib\unittest\case.py", line 329, in run->   testMethod()
02/11/2015 00:34:25 ERROR File "testnemoa.py", line 53, in test_model_algorithm_shallow_ann->   dataset = 'linear', network = 'shallow', system = 'ann')
02/11/2015 00:34:25 ERROR File "./package\nemoa\model\__init__.py", line 22, in create->   return new(**build(*args, **kwargs))
02/11/2015 00:34:25 ERROR File "./package\nemoa\model\__init__.py", line 14, in build->   return nemoa.model.builder.build(*args, **kwargs)
02/11/2015 00:34:25 ERROR File "./package\nemoa\model\builder\__init__.py", line 38, in build->   model = nemoa.model.builder.base.build(type, *args, **kwargs)
02/11/2015 00:34:25 ERROR File "./package\nemoa\model\builder\base.py", line 20, in build->   if type == 'model': return Model(**kwargs).build()
02/11/2015 00:34:25 ERROR File "./package\nemoa\model\builder\base.py", line 77, in build->   = nemoa.dataset.load(self.settings['dataset'])
02/11/2015 00:34:25 ERROR File "./package\nemoa\dataset\__init__.py", line 27, in load->   return nemoa.dataset.imports.load(*args, **kwargs)
02/11/2015 00:34:25 ERROR File "./package\nemoa\dataset\imports\__init__.py", line 44, in load->   '%s'.""" % (workspace, path))
02/11/2015 00:34:25 ERROR File "./package\nemoa\__init__.py", line 32, in log->   return nemoa.common.log.log(*args, **kwargs)
02/11/2015 00:34:25 ERROR File "./package\nemoa\common\log.py", line 174, in log->   for line in traceback.format_stack():
02/11/2015 00:34:25 ERROR nemoa.log -> could not optimize model: dataset is not valid.
02/11/2015 00:34:25 ERROR File "testnemoa.py", line 66, in <module>->   unittest.main()
02/11/2015 00:34:25 ERROR File "C:\Python27\lib\unittest\main.py", line 95, in __init__->   self.runTests()
02/11/2015 00:34:25 ERROR File "C:\Python27\lib\unittest\main.py", line 232, in runTests->   self.result = testRunner.run(self.test)
02/11/2015 00:34:25 ERROR File "C:\Python27\lib\unittest\runner.py", line 151, in run->   test(result)
02/11/2015 00:34:25 ERROR File "C:\Python27\lib\unittest\suite.py", line 70, in __call__->   return self.run(*args, **kwds)
02/11/2015 00:34:25 ERROR File "C:\Python27\lib\unittest\suite.py", line 108, in run->   test(result)
02/11/2015 00:34:25 ERROR File "C:\Python27\lib\unittest\suite.py", line 70, in __call__->   return self.run(*args, **kwds)
02/11/2015 00:34:25 ERROR File "C:\Python27\lib\unittest\suite.py", line 108, in run->   test(result)
02/11/2015 00:34:25 ERROR File "C:\Python27\lib\unittest\case.py", line 393, in __call__->   return self.run(*args, **kwds)
02/11/2015 00:34:25 ERROR File "C:\Python27\lib\unittest\case.py", line 329, in run->   testMethod()
02/11/2015 00:34:25 ERROR File "testnemoa.py", line 54, in test_model_algorithm_shallow_ann->   model.optimize()
02/11/2015 00:34:25 ERROR File "./package\nemoa\model\classes\base.py", line 127, in optimize->   dataset is not valid.""")
02/11/2015 00:34:25 ERROR File "./package\nemoa\__init__.py", line 32, in log->   return nemoa.common.log.log(*args, **kwargs)
02/11/2015 00:34:25 ERROR File "./package\nemoa\common\log.py", line 174, in log->   for line in traceback.format_stack():
02/11/2015 00:34:25 WARNING nemoa.log -> could not open workspace 'unittest': folder could not be found in './user/'.
02/11/2015 00:34:25 WARNING nemoa.log -> could not get configuration: dataset with name 'linear' is not found in common workspace 'benchmark'.
02/11/2015 00:34:25 ERROR nemoa.log -> could not import dataset: workspace 'None' does not contain a dataset with name 'linear'.
02/11/2015 00:34:25 ERROR File "testnemoa.py", line 66, in <module>->   unittest.main()
02/11/2015 00:34:25 ERROR File "C:\Python27\lib\unittest\main.py", line 95, in __init__->   self.runTests()
02/11/2015 00:34:25 ERROR File "C:\Python27\lib\unittest\main.py", line 232, in runTests->   self.result = testRunner.run(self.test)
02/11/2015 00:34:25 ERROR File "C:\Python27\lib\unittest\runner.py", line 151, in run->   test(result)
02/11/2015 00:34:25 ERROR File "C:\Python27\lib\unittest\suite.py", line 70, in __call__->   return self.run(*args, **kwds)
02/11/2015 00:34:25 ERROR File "C:\Python27\lib\unittest\suite.py", line 108, in run->   test(result)
02/11/2015 00:34:25 ERROR File "C:\Python27\lib\unittest\suite.py", line 70, in __call__->   return self.run(*args, **kwds)
02/11/2015 00:34:25 ERROR File "C:\Python27\lib\unittest\suite.py", line 108, in run->   test(result)
02/11/2015 00:34:25 ERROR File "C:\Python27\lib\unittest\case.py", line 393, in __call__->   return self.run(*args, **kwds)
02/11/2015 00:34:25 ERROR File "C:\Python27\lib\unittest\case.py", line 329, in run->   testMethod()
02/11/2015 00:34:25 ERROR File "testnemoa.py", line 41, in test_model_create_ann->   dataset = 'linear', network = 'shallow', system = 'ann')
02/11/2015 00:34:25 ERROR File "./package\nemoa\model\__init__.py", line 22, in create->   return new(**build(*args, **kwargs))
02/11/2015 00:34:25 ERROR File "./package\nemoa\model\__init__.py", line 14, in build->   return nemoa.model.builder.build(*args, **kwargs)
02/11/2015 00:34:25 ERROR File "./package\nemoa\model\builder\__init__.py", line 38, in build->   model = nemoa.model.builder.base.build(type, *args, **kwargs)
02/11/2015 00:34:25 ERROR File "./package\nemoa\model\builder\base.py", line 20, in build->   if type == 'model': return Model(**kwargs).build()
02/11/2015 00:34:25 ERROR File "./package\nemoa\model\builder\base.py", line 77, in build->   = nemoa.dataset.load(self.settings['dataset'])
02/11/2015 00:34:25 ERROR File "./package\nemoa\dataset\__init__.py", line 27, in load->   return nemoa.dataset.imports.load(*args, **kwargs)
02/11/2015 00:34:25 ERROR File "./package\nemoa\dataset\imports\__init__.py", line 44, in load->   '%s'.""" % (workspace, path))
02/11/2015 00:34:25 ERROR File "./package\nemoa\__init__.py", line 32, in log->   return nemoa.common.log.log(*args, **kwargs)
02/11/2015 00:34:25 ERROR File "./package\nemoa\common\log.py", line 174, in log->   for line in traceback.format_stack():
02/11/2015 00:34:25 WARNING nemoa.log -> could not open workspace 'unittest': folder could not be found in './user/'.
02/11/2015 00:34:26 WARNING nemoa.log -> could not get configuration: dataset with name 'linear' is not found in common workspace 'benchmark'.
02/11/2015 00:34:26 ERROR nemoa.log -> could not import dataset: workspace 'None' does not contain a dataset with name 'linear'.
02/11/2015 00:34:26 ERROR File "testnemoa.py", line 66, in <module>->   unittest.main()
02/11/2015 00:34:26 ERROR File "C:\Python27\lib\unittest\main.py", line 95, in __init__->   self.runTests()
02/11/2015 00:34:26 ERROR File "C:\Python27\lib\unittest\main.py", line 232, in runTests->   self.result = testRunner.run(self.test)
02/11/2015 00:34:26 ERROR File "C:\Python27\lib\unittest\runner.py", line 151, in run->   test(result)
02/11/2015 00:34:26 ERROR File "C:\Python27\lib\unittest\suite.py", line 70, in __call__->   return self.run(*args, **kwds)
02/11/2015 00:34:26 ERROR File "C:\Python27\lib\unittest\suite.py", line 108, in run->   test(result)
02/11/2015 00:34:26 ERROR File "C:\Python27\lib\unittest\suite.py", line 70, in __call__->   return self.run(*args, **kwds)
02/11/2015 00:34:26 ERROR File "C:\Python27\lib\unittest\suite.py", line 108, in run->   test(result)
02/11/2015 00:34:26 ERROR File "C:\Python27\lib\unittest\case.py", line 393, in __call__->   return self.run(*args, **kwds)
02/11/2015 00:34:26 ERROR File "C:\Python27\lib\unittest\case.py", line 329, in run->   testMethod()
02/11/2015 00:34:26 ERROR File "testnemoa.py", line 47, in test_model_create_dbn->   dataset = 'linear', network = 'deep', system = 'dbn')
02/11/2015 00:34:26 ERROR File "./package\nemoa\model\__init__.py", line 22, in create->   return new(**build(*args, **kwargs))
02/11/2015 00:34:26 ERROR File "./package\nemoa\model\__init__.py", line 14, in build->   return nemoa.model.builder.build(*args, **kwargs)
02/11/2015 00:34:26 ERROR File "./package\nemoa\model\builder\__init__.py", line 38, in build->   model = nemoa.model.builder.base.build(type, *args, **kwargs)
02/11/2015 00:34:26 ERROR File "./package\nemoa\model\builder\base.py", line 20, in build->   if type == 'model': return Model(**kwargs).build()
02/11/2015 00:34:26 ERROR File "./package\nemoa\model\builder\base.py", line 77, in build->   = nemoa.dataset.load(self.settings['dataset'])
02/11/2015 00:34:26 ERROR File "./package\nemoa\dataset\__init__.py", line 27, in load->   return nemoa.dataset.imports.load(*args, **kwargs)
02/11/2015 00:34:26 ERROR File "./package\nemoa\dataset\imports\__init__.py", line 44, in load->   '%s'.""" % (workspace, path))
02/11/2015 00:34:26 ERROR File "./package\nemoa\__init__.py", line 32, in log->   return nemoa.common.log.log(*args, **kwargs)
02/11/2015 00:34:26 ERROR File "./package\nemoa\common\log.py", line 174, in log->   for line in traceback.format_stack():
02/11/2015 00:34:26 WARNING nemoa.log -> could not open workspace 'unittest': folder could not be found in './user/'.
02/11/2015 00:34:26 WARNING nemoa.log -> could not get configuration: model with name 'test' is not found in common workspace 'benchmark'.
02/11/2015 00:34:26 ERROR nemoa.log -> could not import model: workspace 'None' does not contain a model with name 'test'.
02/11/2015 00:34:26 ERROR File "testnemoa.py", line 66, in <module>->   unittest.main()
02/11/2015 00:34:26 ERROR File "C:\Python27\lib\unittest\main.py", line 95, in __init__->   self.runTests()
02/11/2015 00:34:26 ERROR File "C:\Python27\lib\unittest\main.py", line 232, in runTests->   self.result = testRunner.run(self.test)
02/11/2015 00:34:26 ERROR File "C:\Python27\lib\unittest\runner.py", line 151, in run->   test(result)
02/11/2015 00:34:26 ERROR File "C:\Python27\lib\unittest\suite.py", line 70, in __call__->   return self.run(*args, **kwds)
02/11/2015 00:34:26 ERROR File "C:\Python27\lib\unittest\suite.py", line 108, in run->   test(result)
02/11/2015 00:34:26 ERROR File "C:\Python27\lib\unittest\suite.py", line 70, in __call__->   return self.run(*args, **kwds)
02/11/2015 00:34:26 ERROR File "C:\Python27\lib\unittest\suite.py", line 108, in run->   test(result)
02/11/2015 00:34:26 ERROR File "C:\Python27\lib\unittest\case.py", line 393, in __call__->   return self.run(*args, **kwds)
02/11/2015 00:34:26 ERROR File "C:\Python27\lib\unittest\case.py", line 329, in run->   testMethod()
02/11/2015 00:34:26 ERROR File "testnemoa.py", line 36, in test_model_import_npz->   test = nemoa.common.type.ismodel(nemoa.model.open('test'))
02/11/2015 00:34:26 ERROR File "./package\nemoa\model\__init__.py", line 34, in open->   return new(**load(*args, **kwargs))
02/11/2015 00:34:26 ERROR File "./package\nemoa\model\__init__.py", line 26, in load->   return nemoa.model.imports.load(*args, **kwargs)
02/11/2015 00:34:26 ERROR File "./package\nemoa\model\imports\__init__.py", line 38, in load->   '%s'.""" % (workspace, path))
02/11/2015 00:34:26 ERROR File "./package\nemoa\__init__.py", line 32, in log->   return nemoa.common.log.log(*args, **kwargs)
02/11/2015 00:34:26 ERROR File "./package\nemoa\common\log.py", line 174, in log->   for line in traceback.format_stack():
02/11/2015 00:34:26 WARNING nemoa.log -> could not open workspace 'unittest': folder could not be found in './user/'.
02/11/2015 00:34:26 WARNING nemoa.log -> could not get configuration: network with name 'deep' is not found in common workspace 'benchmark'.
02/11/2015 00:34:26 ERROR nemoa.log -> could not import network: workspace 'None' does not contain a network with name 'deep'.
02/11/2015 00:34:26 ERROR File "testnemoa.py", line 66, in <module>->   unittest.main()
02/11/2015 00:34:26 ERROR File "C:\Python27\lib\unittest\main.py", line 95, in __init__->   self.runTests()
02/11/2015 00:34:26 ERROR File "C:\Python27\lib\unittest\main.py", line 232, in runTests->   self.result = testRunner.run(self.test)
02/11/2015 00:34:26 ERROR File "C:\Python27\lib\unittest\runner.py", line 151, in run->   test(result)
02/11/2015 00:34:26 ERROR File "C:\Python27\lib\unittest\suite.py", line 70, in __call__->   return self.run(*args, **kwds)
02/11/2015 00:34:26 ERROR File "C:\Python27\lib\unittest\suite.py", line 108, in run->   test(result)
02/11/2015 00:34:26 ERROR File "C:\Python27\lib\unittest\suite.py", line 70, in __call__->   return self.run(*args, **kwds)
02/11/2015 00:34:26 ERROR File "C:\Python27\lib\unittest\suite.py", line 108, in run->   test(result)
02/11/2015 00:34:26 ERROR File "C:\Python27\lib\unittest\case.py", line 393, in __call__->   return self.run(*args, **kwds)
02/11/2015 00:34:26 ERROR File "C:\Python27\lib\unittest\case.py", line 329, in run->   testMethod()
02/11/2015 00:34:26 ERROR File "testnemoa.py", line 28, in test_network_import_ini->   test = nemoa.common.type.isnetwork(nemoa.network.open('deep'))
02/11/2015 00:34:26 ERROR File "./package\nemoa\network\__init__.py", line 34, in open->   return new(**load(*args, **kwargs))
02/11/2015 00:34:26 ERROR File "./package\nemoa\network\__init__.py", line 26, in load->   return nemoa.network.imports.load(*args, **kwargs)
02/11/2015 00:34:26 ERROR File "./package\nemoa\network\imports\__init__.py", line 50, in load->   '%s'.""" % (workspace, path))
02/11/2015 00:34:26 ERROR File "./package\nemoa\__init__.py", line 32, in log->   return nemoa.common.log.log(*args, **kwargs)
02/11/2015 00:34:26 ERROR File "./package\nemoa\common\log.py", line 174, in log->   for line in traceback.format_stack():
02/11/2015 00:34:26 ERROR nemoa.log -> could not create network: configuration is not valid.
02/11/2015 00:34:26 ERROR File "testnemoa.py", line 66, in <module>->   unittest.main()
02/11/2015 00:34:26 ERROR File "C:\Python27\lib\unittest\main.py", line 95, in __init__->   self.runTests()
02/11/2015 00:34:26 ERROR File "C:\Python27\lib\unittest\main.py", line 232, in runTests->   self.result = testRunner.run(self.test)
02/11/2015 00:34:26 ERROR File "C:\Python27\lib\unittest\runner.py", line 151, in run->   test(result)
02/11/2015 00:34:26 ERROR File "C:\Python27\lib\unittest\suite.py", line 70, in __call__->   return self.run(*args, **kwds)
02/11/2015 00:34:26 ERROR File "C:\Python27\lib\unittest\suite.py", line 108, in run->   test(result)
02/11/2015 00:34:26 ERROR File "C:\Python27\lib\unittest\suite.py", line 70, in __call__->   return self.run(*args, **kwds)
02/11/2015 00:34:26 ERROR File "C:\Python27\lib\unittest\suite.py", line 108, in run->   test(result)
02/11/2015 00:34:26 ERROR File "C:\Python27\lib\unittest\case.py", line 393, in __call__->   return self.run(*args, **kwds)
02/11/2015 00:34:26 ERROR File "C:\Python27\lib\unittest\case.py", line 329, in run->   testMethod()
02/11/2015 00:34:26 ERROR File "testnemoa.py", line 28, in test_network_import_ini->   test = nemoa.common.type.isnetwork(nemoa.network.open('deep'))
02/11/2015 00:34:26 ERROR File "./package\nemoa\network\__init__.py", line 34, in open->   return new(**load(*args, **kwargs))
02/11/2015 00:34:26 ERROR File "./package\nemoa\network\__init__.py", line 30, in new->   return nemoa.network.classes.new(*args, **kwargs)
02/11/2015 00:34:26 ERROR File "./package\nemoa\network\classes\__init__.py", line 17, in new->   configuration is not valid.""")
02/11/2015 00:34:26 ERROR File "./package\nemoa\__init__.py", line 32, in log->   return nemoa.common.log.log(*args, **kwargs)
02/11/2015 00:34:26 ERROR File "./package\nemoa\common\log.py", line 174, in log->   for line in traceback.format_stack():
02/11/2015 00:34:26 WARNING nemoa.log -> could not open workspace 'unittest': folder could not be found in './user/'.
02/11/2015 00:37:48 WARNING nemoa.log -> could not open workspace 'unittest': folder could not be found in './user/'.
02/11/2015 00:38:17 ERROR nemoa.log -> could not open workspace 'unittest': base of workspace is not valid.
02/11/2015 00:38:17 ERROR File "C:\Python27\lib\runpy.py", line 162, in _run_module_as_main->   "__main__", fname, loader, pkg_name)
02/11/2015 00:38:17 ERROR File "C:\Python27\lib\runpy.py", line 72, in _run_code->   exec code in run_globals
02/11/2015 00:38:17 ERROR File "C:\Python27\Scripts\ipython.exe\__main__.py", line 9, in <module>->   sys.exit(start_ipython())
02/11/2015 00:38:17 ERROR File "C:\Python27\lib\site-packages\IPython\__init__.py", line 120, in start_ipython->   return launch_new_instance(argv=argv, **kwargs)
02/11/2015 00:38:17 ERROR File "C:\Python27\lib\site-packages\IPython\config\application.py", line 564, in launch_instance->   app.start()
02/11/2015 00:38:17 ERROR File "C:\Python27\lib\site-packages\IPython\terminal\ipapp.py", line 371, in start->   self.shell.mainloop()
02/11/2015 00:38:17 ERROR File "C:\Python27\lib\site-packages\IPython\terminal\interactiveshell.py", line 443, in mainloop->   self.interact(display_banner=display_banner)
02/11/2015 00:38:17 ERROR File "C:\Python27\lib\site-packages\IPython\terminal\interactiveshell.py", line 567, in interact->   self.run_cell(source_raw, store_history=True)
02/11/2015 00:38:17 ERROR File "C:\Python27\lib\site-packages\IPython\core\interactiveshell.py", line 2741, in run_cell->   interactivity=interactivity, compiler=compiler)
02/11/2015 00:38:17 ERROR File "C:\Python27\lib\site-packages\IPython\core\interactiveshell.py", line 2833, in run_ast_nodes->   if self.run_code(code):
02/11/2015 00:38:17 ERROR File "C:\Python27\lib\site-packages\IPython\core\interactiveshell.py", line 2883, in run_code->   exec(code_obj, self.user_global_ns, self.user_ns)
02/11/2015 00:38:17 ERROR File "<ipython-input-3-9dce1f903f8f>", line 1, in <module>->   nemoa.open('unittest', base = 'share')
02/11/2015 00:38:17 ERROR File "./package\nemoa\__init__.py", line 40, in open->   return nemoa.workspace.open(workspace, **kwargs)
02/11/2015 00:38:17 ERROR File "./package\nemoa\workspace\__init__.py", line 40, in open->   return nemoa.workspace.base.Workspace(*args, **kwargs)
02/11/2015 00:38:17 ERROR File "./package\nemoa\workspace\base.py", line 24, in __init__->   self.load(workspace, base = base)
02/11/2015 00:38:17 ERROR File "./package\nemoa\workspace\base.py", line 53, in load->   return nemoa.workspace.load(workspace, base = base)
02/11/2015 00:38:17 ERROR File "./package\nemoa\workspace\__init__.py", line 26, in load->   return _shared['config'].load(*args, **kwargs)
02/11/2015 00:38:17 ERROR File "./package\nemoa\workspace\base.py", line 244, in load->   self._set_workspace(workspace, base = base)
02/11/2015 00:38:17 ERROR File "./package\nemoa\workspace\base.py", line 433, in _set_workspace->   '%s': base of workspace is not valid.""" % (workspace))
02/11/2015 00:38:17 ERROR File "./package\nemoa\__init__.py", line 32, in log->   return nemoa.common.log.log(*args, **kwargs)
02/11/2015 00:38:17 ERROR File "./package\nemoa\common\log.py", line 174, in log->   for line in traceback.format_stack():
02/11/2015 00:38:22 ERROR nemoa.log -> could not open workspace 'unittest': base of workspace is not valid.
02/11/2015 00:38:22 ERROR File "C:\Python27\lib\runpy.py", line 162, in _run_module_as_main->   "__main__", fname, loader, pkg_name)
02/11/2015 00:38:22 ERROR File "C:\Python27\lib\runpy.py", line 72, in _run_code->   exec code in run_globals
02/11/2015 00:38:22 ERROR File "C:\Python27\Scripts\ipython.exe\__main__.py", line 9, in <module>->   sys.exit(start_ipython())
02/11/2015 00:38:22 ERROR File "C:\Python27\lib\site-packages\IPython\__init__.py", line 120, in start_ipython->   return launch_new_instance(argv=argv, **kwargs)
02/11/2015 00:38:22 ERROR File "C:\Python27\lib\site-packages\IPython\config\application.py", line 564, in launch_instance->   app.start()
02/11/2015 00:38:22 ERROR File "C:\Python27\lib\site-packages\IPython\terminal\ipapp.py", line 371, in start->   self.shell.mainloop()
02/11/2015 00:38:22 ERROR File "C:\Python27\lib\site-packages\IPython\terminal\interactiveshell.py", line 443, in mainloop->   self.interact(display_banner=display_banner)
02/11/2015 00:38:22 ERROR File "C:\Python27\lib\site-packages\IPython\terminal\interactiveshell.py", line 567, in interact->   self.run_cell(source_raw, store_history=True)
02/11/2015 00:38:22 ERROR File "C:\Python27\lib\site-packages\IPython\core\interactiveshell.py", line 2741, in run_cell->   interactivity=interactivity, compiler=compiler)
02/11/2015 00:38:22 ERROR File "C:\Python27\lib\site-packages\IPython\core\interactiveshell.py", line 2833, in run_ast_nodes->   if self.run_code(code):
02/11/2015 00:38:22 ERROR File "C:\Python27\lib\site-packages\IPython\core\interactiveshell.py", line 2883, in run_code->   exec(code_obj, self.user_global_ns, self.user_ns)
02/11/2015 00:38:22 ERROR File "<ipython-input-4-09b896de3850>", line 1, in <module>->   nemoa.open('unittest', base = 'shared')
02/11/2015 00:38:22 ERROR File "./package\nemoa\__init__.py", line 40, in open->   return nemoa.workspace.open(workspace, **kwargs)
02/11/2015 00:38:22 ERROR File "./package\nemoa\workspace\__init__.py", line 40, in open->   return nemoa.workspace.base.Workspace(*args, **kwargs)
02/11/2015 00:38:22 ERROR File "./package\nemoa\workspace\base.py", line 24, in __init__->   self.load(workspace, base = base)
02/11/2015 00:38:22 ERROR File "./package\nemoa\workspace\base.py", line 53, in load->   return nemoa.workspace.load(workspace, base = base)
02/11/2015 00:38:22 ERROR File "./package\nemoa\workspace\__init__.py", line 26, in load->   return _shared['config'].load(*args, **kwargs)
02/11/2015 00:38:22 ERROR File "./package\nemoa\workspace\base.py", line 244, in load->   self._set_workspace(workspace, base = base)
02/11/2015 00:38:22 ERROR File "./package\nemoa\workspace\base.py", line 433, in _set_workspace->   '%s': base of workspace is not valid.""" % (workspace))
02/11/2015 00:38:22 ERROR File "./package\nemoa\__init__.py", line 32, in log->   return nemoa.common.log.log(*args, **kwargs)
02/11/2015 00:38:22 ERROR File "./package\nemoa\common\log.py", line 174, in log->   for line in traceback.format_stack():
