11/10/2014 14:21:13 ERROR nemoa.dataset.exports.image.show -> could not plot dataset 'data': plot type 'correlation' is not supported.
11/10/2014 14:21:13 ERROR File "/usr/bin/ipython", line 6, in <module>->   start_ipython()
11/10/2014 14:21:13 ERROR File "/usr/lib/python2.7/dist-packages/IPython/__init__.py", line 118, in start_ipython->   return launch_new_instance(argv=argv, **kwargs)
11/10/2014 14:21:13 ERROR File "/usr/lib/python2.7/dist-packages/IPython/config/application.py", line 546, in launch_instance->   app.start()
11/10/2014 14:21:13 ERROR File "/usr/lib/python2.7/dist-packages/IPython/terminal/ipapp.py", line 362, in start->   self.shell.mainloop()
11/10/2014 14:21:13 ERROR File "/usr/lib/python2.7/dist-packages/IPython/terminal/interactiveshell.py", line 436, in mainloop->   self.interact(display_banner=display_banner)
11/10/2014 14:21:13 ERROR File "/usr/lib/python2.7/dist-packages/IPython/terminal/interactiveshell.py", line 555, in interact->   self.run_cell(source_raw, store_history=True)
11/10/2014 14:21:13 ERROR File "/usr/lib/python2.7/dist-packages/IPython/core/interactiveshell.py", line 2660, in run_cell->   interactivity=interactivity, compiler=compiler)
11/10/2014 14:21:13 ERROR File "/usr/lib/python2.7/dist-packages/IPython/core/interactiveshell.py", line 2770, in run_ast_nodes->   if self.run_code(code):
11/10/2014 14:21:13 ERROR File "/usr/lib/python2.7/dist-packages/IPython/core/interactiveshell.py", line 2820, in run_code->   exec code_obj in self.user_global_ns, self.user_ns
11/10/2014 14:21:13 ERROR File "<ipython-input-3-64ed89f05e46>", line 1, in <module>->   dataset.show('correlation')
11/10/2014 14:21:13 ERROR File "./package/nemoa/dataset/classes/base.py", line 1409, in show->   return nemoa.dataset.show(self, *args, **kwargs)
11/10/2014 14:21:13 ERROR File "./package/nemoa/dataset/__init__.py", line 39, in show->   return nemoa.dataset.exports.show(*args, **kwargs)
11/10/2014 14:21:13 ERROR File "./package/nemoa/dataset/exports/__init__.py", line 108, in show->   return nemoa.dataset.exports.image.show(dataset, *args, **kwargs)
11/10/2014 14:21:13 ERROR File "./package/nemoa/dataset/exports/image.py", line 28, in show->   plot type '%s' is not supported.""" % (dataset.name, plot))
11/10/2014 14:21:13 ERROR File "./package/nemoa/common/log.py", line 164, in log->   for line in traceback.format_stack():
